<sdf version='1.7'>
  <world name='default'>
    <light name='sun' type='directional'>
      <cast_shadows>1</cast_shadows>
      <pose>0 0 10 0 -0 0</pose>
      <diffuse>0.8 0.8 0.8 1</diffuse>
      <specular>0.2 0.2 0.2 1</specular>
      <attenuation>
        <range>1000</range>
        <constant>0.9</constant>
        <linear>0.01</linear>
        <quadratic>0.001</quadratic>
      </attenuation>
      <direction>-0.5 0.1 -0.9</direction>
      <spot>
        <inner_angle>0</inner_angle>
        <outer_angle>0</outer_angle>
        <falloff>0</falloff>
      </spot>
    </light>
    <model name='ground_plane'>
      <static>1</static>
      <link name='link'>
        <collision name='collision'>
          <geometry>
            <plane>
              <normal>0 0 1</normal>
              <size>100 100</size>
            </plane>
          </geometry>
          <surface>
            <friction>
              <ode>
                <mu>100</mu>
                <mu2>50</mu2>
              </ode>
              <torsional>
                <ode/>
              </torsional>
            </friction>
            <contact>
              <ode/>
            </contact>
            <bounce/>
          </surface>
          <max_contacts>10</max_contacts>
        </collision>
        <visual name='visual'>
          <cast_shadows>0</cast_shadows>
          <geometry>
            <plane>
              <normal>0 0 1</normal>
              <size>100 100</size>
            </plane>
          </geometry>
          <material>
            <script>
              <uri>file://media/materials/scripts/gazebo.material</uri>
              <name>Gazebo/Grey</name>
            </script>
          </material>
        </visual>
        <self_collide>0</self_collide>
        <enable_wind>0</enable_wind>
        <kinematic>0</kinematic>
      </link>
    </model>
    <gravity>0 0 -9.8</gravity>
    <magnetic_field>6e-06 2.3e-05 -4.2e-05</magnetic_field>
    <atmosphere type='adiabatic'/>
    <physics type='ode'>
      <max_step_size>0.001</max_step_size>
      <real_time_factor>1</real_time_factor>
      <real_time_update_rate>1000</real_time_update_rate>
    </physics>
    <scene>
      <ambient>0.4 0.4 0.4 1</ambient>
      <background>0.7 0.7 0.7 1</background>
      <shadows>1</shadows>
    </scene>
    <audio>
      <device>default</device>
    </audio>
    <wind/>
    <spherical_coordinates>
      <surface_model>EARTH_WGS84</surface_model>
      <latitude_deg>0</latitude_deg>
      <longitude_deg>0</longitude_deg>
      <elevation>0</elevation>
      <heading_deg>0</heading_deg>
    </spherical_coordinates>
    <model name='my_bot'>
      <link name='base_link'>
        <inertial>
          <pose>0.016641 9.1e-05 -0.089499 0 -0 0</pose>
          <mass>8.61221</mass>
          <inertia>
            <ixx>0.619106</ixx>
            <ixy>-1.34315e-06</ixy>
            <ixz>0.00686548</ixz>
            <iyy>1.29237</iyy>
            <iyz>3.59477e-05</iyz>
            <izz>1.10239</izz>
          </inertia>
        </inertial>
        <collision name='base_link_collision'>
          <pose>0 0 0 0 -0 0</pose>
          <geometry>
            <mesh>
              <scale>1 1 1</scale>
              <uri>src/diablo_bot/description/meshes/base_link.STL</uri>
            </mesh>
          </geometry>
          <surface>
            <contact>
              <ode/>
            </contact>
            <friction>
              <ode/>
              <torsional>
                <ode/>
              </torsional>
            </friction>
            <bounce/>
          </surface>
          <max_contacts>10</max_contacts>
        </collision>
        <collision name='base_link_fixed_joint_lump__head_pan_Link_collision_1'>
          <pose>-0.012051 0 0.3059 0 -0 1.5708</pose>
          <geometry>
            <mesh>
              <scale>1 1 1</scale>
              <uri>src/diablo_bot/description/meshes/head_pan_Link.STL</uri>
            </mesh>
          </geometry>
          <max_contacts>10</max_contacts>
          <surface>
            <contact>
              <ode/>
            </contact>
            <bounce/>
            <friction>
              <torsional>
                <ode/>
              </torsional>
              <ode/>
            </friction>
          </surface>
        </collision>
        <collision name='base_link_fixed_joint_lump__head_tilt_Link_collision_2'>
          <pose>0.000949 0.024 0.3189 1.5708 -0 0</pose>
          <geometry>
            <mesh>
              <scale>1 1 1</scale>
              <uri>src/diablo_bot/description/meshes/head_tilt_Link.STL</uri>
            </mesh>
          </geometry>
          <max_contacts>10</max_contacts>
          <surface>
            <contact>
              <ode/>
            </contact>
            <bounce/>
            <friction>
              <torsional>
                <ode/>
              </torsional>
              <ode/>
            </friction>
          </surface>
        </collision>
        <collision name='base_link_fixed_joint_lump__lower_base_link_collision_3'>
          <pose>0 0 -0.5 0 -0 0</pose>
          <geometry>
            <mesh>
              <scale>0.001 0.001 0.001</scale>
              <uri>src/diablo_bot/description/meshes/lower_base_link.stl</uri>
            </mesh>
          </geometry>
          <max_contacts>10</max_contacts>
          <surface>
            <contact>
              <ode/>
            </contact>
            <bounce/>
            <friction>
              <torsional>
                <ode/>
              </torsional>
              <ode/>
            </friction>
          </surface>
        </collision>
        <visual name='base_link_visual'>
          <pose>0 0 0 0 -0 0</pose>
          <geometry>
            <mesh>
              <scale>1 1 1</scale>
              <uri>src/diablo_bot/description/meshes/base_link.STL</uri>
            </mesh>
          </geometry>
          <material>
            <script>
              <name>Gazebo/Black</name>
              <uri>file://media/materials/scripts/gazebo.material</uri>
            </script>
          </material>
        </visual>
        <visual name='base_link_fixed_joint_lump__head_pan_Link_visual_1'>
          <pose>-0.012051 0 0.3059 0 -0 1.5708</pose>
          <geometry>
            <mesh>
              <scale>1 1 1</scale>
              <uri>src/diablo_bot/description/meshes/head_pan_Link.STL</uri>
            </mesh>
          </geometry>
        </visual>
        <visual name='base_link_fixed_joint_lump__head_tilt_Link_visual_2'>
          <pose>0.000949 0.024 0.3189 1.5708 -0 0</pose>
          <geometry>
            <mesh>
              <scale>1 1 1</scale>
              <uri>src/diablo_bot/description/meshes/head_tilt_Link.STL</uri>
            </mesh>
          </geometry>
        </visual>
        <visual name='base_link_fixed_joint_lump__lower_base_link_visual_3'>
          <pose>0 0 -0.5 0 -0 0</pose>
          <geometry>
            <mesh>
              <scale>0.001 0.001 0.001</scale>
              <uri>src/diablo_bot/description/meshes/lower_base_link.stl</uri>
            </mesh>
          </geometry>
        </visual>
        <self_collide>0</self_collide>
        <enable_wind>0</enable_wind>
        <kinematic>0</kinematic>
      </link>
      <joint name='l_sho_pitch' type='revolute'>
        <pose relative_to='base_link'>-0.012051 0.09965 0.26225 1.5708 -0 3.14159</pose>
        <parent>base_link</parent>
        <child>l_sho_pitch_Link</child>
        <axis>
          <xyz>0 0 -1</xyz>
          <limit>
            <lower>0</lower>
            <upper>0</upper>
            <effort>4.1</effort>
            <velocity>4.71</velocity>
          </limit>
          <dynamics>
            <spring_reference>0</spring_reference>
            <spring_stiffness>0</spring_stiffness>
          </dynamics>
        </axis>
      </joint>
      <link name='l_sho_pitch_Link'>
        <pose relative_to='l_sho_pitch'>0 0 0 0 -0 0</pose>
        <inertial>
          <pose>-0.000541 -0 0.024565 0 -0 0</pose>
          <mass>0.0454925</mass>
          <inertia>
            <ixx>1.06543e-05</ixx>
            <ixy>4.23803e-20</ixy>
            <ixz>-1.18102e-09</ixz>
            <iyy>1.2432e-05</iyy>
            <iyz>2.70982e-20</iyz>
            <izz>7.52175e-06</izz>
          </inertia>
        </inertial>
        <collision name='l_sho_pitch_Link_collision'>
          <pose>0 0 0 0 -0 0</pose>
          <geometry>
            <mesh>
              <scale>1 1 1</scale>
              <uri>src/diablo_bot/description/meshes/l_sho_pitch_Link.STL</uri>
            </mesh>
          </geometry>
          <max_contacts>10</max_contacts>
          <surface>
            <contact>
              <ode/>
            </contact>
            <bounce/>
            <friction>
              <torsional>
                <ode/>
              </torsional>
              <ode/>
            </friction>
          </surface>
        </collision>
        <visual name='l_sho_pitch_Link_visual'>
          <pose>0 0 0 0 -0 0</pose>
          <geometry>
            <mesh>
              <scale>1 1 1</scale>
              <uri>src/diablo_bot/description/meshes/l_sho_pitch_Link.STL</uri>
            </mesh>
          </geometry>
        </visual>
        <self_collide>0</self_collide>
        <enable_wind>0</enable_wind>
        <kinematic>0</kinematic>
      </link>
      <joint name='l_sho_roll' type='revolute'>
        <pose relative_to='l_sho_pitch_Link'>-0.0234 0 0.03735 3.14159 1.57079 3.14159</pose>
        <parent>l_sho_pitch_Link</parent>
        <child>l_sho_roll_Link</child>
        <axis>
          <xyz>0 0 1</xyz>
          <limit>
            <lower>0.9</lower>
            <upper>1.6</upper>
            <effort>4.1</effort>
            <velocity>4.71</velocity>
          </limit>
          <dynamics>
            <spring_reference>0</spring_reference>
            <spring_stiffness>0</spring_stiffness>
          </dynamics>
        </axis>
      </joint>
      <link name='l_sho_roll_Link'>
        <pose relative_to='l_sho_roll'>0 0 0 0 -0 0</pose>
        <inertial>
          <pose>-0.114571 0.000361 0.0234 0 -0 0</pose>
          <mass>0.0683067</mass>
          <inertia>
            <ixx>1.14189e-05</ixx>
            <ixy>-1.22523e-09</ixy>
            <ixz>7.04706e-13</ixz>
            <iyy>2.35951e-05</iyy>
            <iyz>1.56834e-13</iyz>
            <izz>2.34186e-05</izz>
          </inertia>
        </inertial>
        <collision name='l_sho_roll_Link_collision'>
          <pose>0 0 0 0 -0 0</pose>
          <geometry>
            <mesh>
              <scale>1 1 1</scale>
              <uri>src/diablo_bot/description/meshes/l_sho_roll_Link.STL</uri>
            </mesh>
          </geometry>
          <max_contacts>10</max_contacts>
          <surface>
            <contact>
              <ode/>
            </contact>
            <bounce/>
            <friction>
              <torsional>
                <ode/>
              </torsional>
              <ode/>
            </friction>
          </surface>
        </collision>
        <visual name='l_sho_roll_Link_visual'>
          <pose>0 0 0 0 -0 0</pose>
          <geometry>
            <mesh>
              <scale>1 1 1</scale>
              <uri>src/diablo_bot/description/meshes/l_sho_roll_Link.STL</uri>
            </mesh>
          </geometry>
        </visual>
        <self_collide>0</self_collide>
        <enable_wind>0</enable_wind>
        <kinematic>0</kinematic>
      </link>
      <joint name='l_el' type='revolute'>
        <pose relative_to='l_sho_roll_Link'>-0.14975 0.0234 0.0234 1.5708 -0 3.14159</pose>
        <parent>l_sho_roll_Link</parent>
        <child>l_el_Link</child>
        <axis>
          <xyz>0 0 -1</xyz>
          <limit>
            <lower>0</lower>
            <upper>1.57</upper>
            <effort>4.1</effort>
            <velocity>4.71</velocity>
          </limit>
          <dynamics>
            <spring_reference>0</spring_reference>
            <spring_stiffness>0</spring_stiffness>
          </dynamics>
        </axis>
      </joint>
      <link name='l_el_Link'>
        <pose relative_to='l_el'>0 0 0 0 -0 0</pose>
        <inertial>
          <pose>0.068089 0.001693 -0.026861 0 -0 0</pose>
          <mass>0.305317</mass>
          <inertia>
            <ixx>0.0975728</ixx>
            <ixy>-0.000378491</ixy>
            <ixz>-0.000297669</ixz>
            <iyy>1.0178</iyy>
            <iyz>0.00159419</iyz>
            <izz>0.931972</izz>
          </inertia>
        </inertial>
        <collision name='l_el_Link_collision'>
          <pose>0 0 0 0 -0 0</pose>
          <geometry>
            <mesh>
              <scale>1 1 1</scale>
              <uri>src/diablo_bot/description/meshes/l_el_Link.STL</uri>
            </mesh>
          </geometry>
          <max_contacts>10</max_contacts>
          <surface>
            <contact>
              <ode/>
            </contact>
            <bounce/>
            <friction>
              <torsional>
                <ode/>
              </torsional>
              <ode/>
            </friction>
          </surface>
        </collision>
        <collision name='l_el_Link_fixed_joint_lump__l_wrist_Link_collision_1'>
          <pose>0.091 0.000113 -0.023557 1.5708 -0 1.53589</pose>
          <geometry>
            <mesh>
              <scale>1 1 1</scale>
              <uri>src/diablo_bot/description/meshes/l_wrist_Link.STL</uri>
            </mesh>
          </geometry>
          <max_contacts>10</max_contacts>
          <surface>
            <contact>
              <ode/>
            </contact>
            <bounce/>
            <friction>
              <torsional>
                <ode/>
              </torsional>
              <ode/>
            </friction>
          </surface>
        </collision>
        <collision name='l_el_Link_fixed_joint_lump__l_index_base_Link_collision_2'>
          <pose>0.185941 0.014719 -0.008655 -4e-06 0 -1e-05</pose>
          <geometry>
            <mesh>
              <scale>1 1 1</scale>
              <uri>src/diablo_bot/description/meshes/l_index_base_Link.STL</uri>
            </mesh>
          </geometry>
          <max_contacts>10</max_contacts>
          <surface>
            <contact>
              <ode/>
            </contact>
            <bounce/>
            <friction>
              <torsional>
                <ode/>
              </torsional>
              <ode/>
            </friction>
          </surface>
        </collision>
        <collision name='l_el_Link_fixed_joint_lump__l_index_middle_Link_collision_3'>
          <pose>0.200476 0.021508 -0.007947 -4e-06 0 -1e-05</pose>
          <geometry>
            <mesh>
              <scale>1 1 1</scale>
              <uri>src/diablo_bot/description/meshes/l_index_middle_Link.STL</uri>
            </mesh>
          </geometry>
          <max_contacts>10</max_contacts>
          <surface>
            <contact>
              <ode/>
            </contact>
            <bounce/>
            <friction>
              <torsional>
                <ode/>
              </torsional>
              <ode/>
            </friction>
          </surface>
        </collision>
        <collision name='l_el_Link_fixed_joint_lump__l_index_tip_Link_collision_4'>
          <pose>0.21542 0.02694 -0.006152 -4e-06 0 -1e-05</pose>
          <geometry>
            <mesh>
              <scale>1 1 1</scale>
              <uri>src/diablo_bot/description/meshes/l_index_tip_Link.STL</uri>
            </mesh>
          </geometry>
          <max_contacts>10</max_contacts>
          <surface>
            <contact>
              <ode/>
            </contact>
            <bounce/>
            <friction>
              <torsional>
                <ode/>
              </torsional>
              <ode/>
            </friction>
          </surface>
        </collision>
        <collision name='l_el_Link_fixed_joint_lump__l_mid_base_Link_collision_5'>
          <pose>0.184747 0.013656 -0.0491 -4e-06 0 -1e-05</pose>
          <geometry>
            <mesh>
              <scale>1 1 1</scale>
              <uri>src/diablo_bot/description/meshes/l_mid_base_Link.STL</uri>
            </mesh>
          </geometry>
          <max_contacts>10</max_contacts>
          <surface>
            <contact>
              <ode/>
            </contact>
            <bounce/>
            <friction>
              <torsional>
                <ode/>
              </torsional>
              <ode/>
            </friction>
          </surface>
        </collision>
        <collision name='l_el_Link_fixed_joint_lump__l_mid_middle_Link_collision_6'>
          <pose>0.198972 0.020221 -0.052623 -4e-06 0 -1e-05</pose>
          <geometry>
            <mesh>
              <scale>1 1 1</scale>
              <uri>src/diablo_bot/description/meshes/l_mid_middle_Link.STL</uri>
            </mesh>
          </geometry>
          <max_contacts>10</max_contacts>
          <surface>
            <contact>
              <ode/>
            </contact>
            <bounce/>
            <friction>
              <torsional>
                <ode/>
              </torsional>
              <ode/>
            </friction>
          </surface>
        </collision>
        <collision name='l_el_Link_fixed_joint_lump__l_mid_tip_Link_collision_7'>
          <pose>0.213888 0.025603 -0.054755 -4e-06 0 -1e-05</pose>
          <geometry>
            <mesh>
              <scale>1 1 1</scale>
              <uri>src/diablo_bot/description/meshes/l_mid_tip_Link.STL</uri>
            </mesh>
          </geometry>
          <max_contacts>10</max_contacts>
          <surface>
            <contact>
              <ode/>
            </contact>
            <bounce/>
            <friction>
              <torsional>
                <ode/>
              </torsional>
              <ode/>
            </friction>
          </surface>
        </collision>
        <collision name='l_el_Link_fixed_joint_lump__l_thumb_base_Link_collision_8'>
          <pose>0.169953 -0.026716 -0.018084 -4e-06 0 -1e-05</pose>
          <geometry>
            <mesh>
              <scale>1 1 1</scale>
              <uri>src/diablo_bot/description/meshes/l_thumb_base_Link.STL</uri>
            </mesh>
          </geometry>
          <max_contacts>10</max_contacts>
          <surface>
            <contact>
              <ode/>
            </contact>
            <bounce/>
            <friction>
              <torsional>
                <ode/>
              </torsional>
              <ode/>
            </friction>
          </surface>
        </collision>
        <collision name='l_el_Link_fixed_joint_lump__l_thumb_middle_Link_collision_9'>
          <pose>0.175425 -0.041849 -0.029822 -4e-06 0 -1e-05</pose>
          <geometry>
            <mesh>
              <scale>1 1 1</scale>
              <uri>src/diablo_bot/description/meshes/l_thumb_middle_Link.STL</uri>
            </mesh>
          </geometry>
          <max_contacts>10</max_contacts>
          <surface>
            <contact>
              <ode/>
            </contact>
            <bounce/>
            <friction>
              <torsional>
                <ode/>
              </torsional>
              <ode/>
            </friction>
          </surface>
        </collision>
        <collision name='l_el_Link_fixed_joint_lump__l_thumb_tip_Link_collision_10'>
          <pose>0.180897 -0.056884 -0.029697 -4e-06 0 -1e-05</pose>
          <geometry>
            <mesh>
              <scale>1 1 1</scale>
              <uri>src/diablo_bot/description/meshes/l_thumb_tip_Link.STL</uri>
            </mesh>
          </geometry>
          <max_contacts>10</max_contacts>
          <surface>
            <contact>
              <ode/>
            </contact>
            <bounce/>
            <friction>
              <torsional>
                <ode/>
              </torsional>
              <ode/>
            </friction>
          </surface>
        </collision>
        <visual name='l_el_Link_visual'>
          <pose>0 0 0 0 -0 0</pose>
          <geometry>
            <mesh>
              <scale>1 1 1</scale>
              <uri>src/diablo_bot/description/meshes/l_el_Link.STL</uri>
            </mesh>
          </geometry>
        </visual>
        <visual name='l_el_Link_fixed_joint_lump__l_wrist_Link_visual_1'>
          <pose>0.091 0.000113 -0.023557 1.5708 -0 1.53589</pose>
          <geometry>
            <mesh>
              <scale>1 1 1</scale>
              <uri>src/diablo_bot/description/meshes/l_wrist_Link.STL</uri>
            </mesh>
          </geometry>
        </visual>
        <visual name='l_el_Link_fixed_joint_lump__l_index_base_Link_visual_2'>
          <pose>0.185941 0.014719 -0.008655 -4e-06 0 -1e-05</pose>
          <geometry>
            <mesh>
              <scale>1 1 1</scale>
              <uri>src/diablo_bot/description/meshes/l_index_base_Link.STL</uri>
            </mesh>
          </geometry>
        </visual>
        <visual name='l_el_Link_fixed_joint_lump__l_index_middle_Link_visual_3'>
          <pose>0.200476 0.021508 -0.007947 -4e-06 0 -1e-05</pose>
          <geometry>
            <mesh>
              <scale>1 1 1</scale>
              <uri>src/diablo_bot/description/meshes/l_index_middle_Link.STL</uri>
            </mesh>
          </geometry>
        </visual>
        <visual name='l_el_Link_fixed_joint_lump__l_index_tip_Link_visual_4'>
          <pose>0.21542 0.02694 -0.006152 -4e-06 0 -1e-05</pose>
          <geometry>
            <mesh>
              <scale>1 1 1</scale>
              <uri>src/diablo_bot/description/meshes/l_index_tip_Link.STL</uri>
            </mesh>
          </geometry>
        </visual>
        <visual name='l_el_Link_fixed_joint_lump__l_mid_base_Link_visual_5'>
          <pose>0.184747 0.013656 -0.0491 -4e-06 0 -1e-05</pose>
          <geometry>
            <mesh>
              <scale>1 1 1</scale>
              <uri>src/diablo_bot/description/meshes/l_mid_base_Link.STL</uri>
            </mesh>
          </geometry>
        </visual>
        <visual name='l_el_Link_fixed_joint_lump__l_mid_middle_Link_visual_6'>
          <pose>0.198972 0.020221 -0.052623 -4e-06 0 -1e-05</pose>
          <geometry>
            <mesh>
              <scale>1 1 1</scale>
              <uri>src/diablo_bot/description/meshes/l_mid_middle_Link.STL</uri>
            </mesh>
          </geometry>
        </visual>
        <visual name='l_el_Link_fixed_joint_lump__l_mid_tip_Link_visual_7'>
          <pose>0.213888 0.025603 -0.054755 -4e-06 0 -1e-05</pose>
          <geometry>
            <mesh>
              <scale>1 1 1</scale>
              <uri>src/diablo_bot/description/meshes/l_mid_tip_Link.STL</uri>
            </mesh>
          </geometry>
        </visual>
        <visual name='l_el_Link_fixed_joint_lump__l_thumb_base_Link_visual_8'>
          <pose>0.169953 -0.026716 -0.018084 -4e-06 0 -1e-05</pose>
          <geometry>
            <mesh>
              <scale>1 1 1</scale>
              <uri>src/diablo_bot/description/meshes/l_thumb_base_Link.STL</uri>
            </mesh>
          </geometry>
        </visual>
        <visual name='l_el_Link_fixed_joint_lump__l_thumb_middle_Link_visual_9'>
          <pose>0.175425 -0.041849 -0.029822 -4e-06 0 -1e-05</pose>
          <geometry>
            <mesh>
              <scale>1 1 1</scale>
              <uri>src/diablo_bot/description/meshes/l_thumb_middle_Link.STL</uri>
            </mesh>
          </geometry>
        </visual>
        <visual name='l_el_Link_fixed_joint_lump__l_thumb_tip_Link_visual_10'>
          <pose>0.180897 -0.056884 -0.029697 -4e-06 0 -1e-05</pose>
          <geometry>
            <mesh>
              <scale>1 1 1</scale>
              <uri>src/diablo_bot/description/meshes/l_thumb_tip_Link.STL</uri>
            </mesh>
          </geometry>
        </visual>
        <self_collide>0</self_collide>
        <enable_wind>0</enable_wind>
        <kinematic>0</kinematic>
      </link>
      <joint name='l1' type='revolute'>
        <pose relative_to='base_link'>0.00036 0.053553 -0.121 0 -0 0</pose>
        <parent>base_link</parent>
        <child>motor_left_link_1</child>
        <axis>
          <xyz>0 1 0</xyz>
          <limit>
            <effort>9.6</effort>
            <velocity>12.05</velocity>
            <lower>-1e+16</lower>
            <upper>1e+16</upper>
          </limit>
          <dynamics>
            <damping>0</damping>
            <friction>0</friction>
            <spring_reference>0</spring_reference>
            <spring_stiffness>0</spring_stiffness>
          </dynamics>
        </axis>
      </joint>
      <link name='motor_left_link_1'>
        <pose relative_to='l1'>0 0 0 0 -0 0</pose>
        <inertial>
          <pose>0.000158 0.067983 -0.001799 0 -0 0</pose>
          <mass>4.65</mass>
          <inertia>
            <ixx>0.0300227</ixx>
            <ixy>-4.25399e-05</ixy>
            <ixz>0.000229131</ixz>
            <iyy>0.0300775</iyy>
            <iyz>0.000679053</iyz>
            <izz>0.0267843</izz>
          </inertia>
        </inertial>
        <collision name='motor_left_link_1_collision'>
          <pose>-0.00036 -0.053553 -0.379 0 -0 0</pose>
          <geometry>
            <mesh>
              <scale>0.001 0.001 0.001</scale>
              <uri>src/diablo_bot/description/meshes/motor_left_link_1.stl</uri>
            </mesh>
          </geometry>
          <max_contacts>10</max_contacts>
          <surface>
            <contact>
              <ode/>
            </contact>
            <bounce/>
            <friction>
              <torsional>
                <ode/>
              </torsional>
              <ode/>
            </friction>
          </surface>
        </collision>
        <collision name='motor_left_link_1_fixed_joint_lump__leg_left_link_1_collision_1'>
          <pose>-0.00036 -0.053553 -0.379 0 -0 0</pose>
          <geometry>
            <mesh>
              <scale>0.001 0.001 0.001</scale>
              <uri>src/diablo_bot/description/meshes/leg_left_link_1.stl</uri>
            </mesh>
          </geometry>
          <max_contacts>10</max_contacts>
          <surface>
            <contact>
              <ode/>
            </contact>
            <bounce/>
            <friction>
              <torsional>
                <ode/>
              </torsional>
              <ode/>
            </friction>
          </surface>
        </collision>
        <visual name='motor_left_link_1_visual'>
          <pose>-0.00036 -0.053553 -0.379 0 -0 0</pose>
          <geometry>
            <mesh>
              <scale>0.001 0.001 0.001</scale>
              <uri>src/diablo_bot/description/meshes/motor_left_link_1.stl</uri>
            </mesh>
          </geometry>
        </visual>
        <visual name='motor_left_link_1_fixed_joint_lump__leg_left_link_1_visual_1'>
          <pose>-0.00036 -0.053553 -0.379 0 -0 0</pose>
          <geometry>
            <mesh>
              <scale>0.001 0.001 0.001</scale>
              <uri>src/diablo_bot/description/meshes/leg_left_link_1.stl</uri>
            </mesh>
          </geometry>
        </visual>
        <self_collide>0</self_collide>
        <enable_wind>0</enable_wind>
        <kinematic>0</kinematic>
      </link>
      <joint name='l3' type='revolute'>
        <pose relative_to='motor_left_link_1'>0 0.1341 -0.14 0 -0 0</pose>
        <parent>motor_left_link_1</parent>
        <child>leg2_left_link_1</child>
        <axis>
          <xyz>0 1 0</xyz>
          <limit>
            <effort>9.6</effort>
            <velocity>12.05</velocity>
            <lower>-1e+16</lower>
            <upper>1e+16</upper>
          </limit>
          <dynamics>
            <damping>0</damping>
            <friction>0</friction>
            <spring_reference>0</spring_reference>
            <spring_stiffness>0</spring_stiffness>
          </dynamics>
        </axis>
      </joint>
      <link name='leg2_left_link_1'>
        <pose relative_to='l3'>0 0 0 0 -0 0</pose>
        <inertial>
          <pose>2e-06 0.012348 -0.092364 0 -0 0</pose>
          <mass>0.05</mass>
          <inertia>
            <ixx>0.003787</ixx>
            <ixy>0</ixy>
            <ixz>0</ixz>
            <iyy>0.003963</iyy>
            <iyz>5.8e-05</iyz>
            <izz>0.000327</izz>
          </inertia>
        </inertial>
        <collision name='leg2_left_link_1_collision'>
          <pose>-0.00036 -0.187653 -0.239 0 -0 0</pose>
          <geometry>
            <mesh>
              <scale>0.001 0.001 0.001</scale>
              <uri>src/diablo_bot/description/meshes/leg2_left_link_1.stl</uri>
            </mesh>
          </geometry>
          <max_contacts>10</max_contacts>
          <surface>
            <contact>
              <ode/>
            </contact>
            <bounce/>
            <friction>
              <torsional>
                <ode/>
              </torsional>
              <ode/>
            </friction>
          </surface>
        </collision>
        <visual name='leg2_left_link_1_visual'>
          <pose>-0.00036 -0.187653 -0.239 0 -0 0</pose>
          <geometry>
            <mesh>
              <scale>0.001 0.001 0.001</scale>
              <uri>src/diablo_bot/description/meshes/leg2_left_link_1.stl</uri>
            </mesh>
          </geometry>
        </visual>
        <self_collide>0</self_collide>
        <enable_wind>0</enable_wind>
        <kinematic>0</kinematic>
      </link>
      <joint name='l4' type='revolute'>
        <pose relative_to='leg2_left_link_1'>0 0.0277 -0.14 0 -0 0</pose>
        <parent>leg2_left_link_1</parent>
        <child>wheel_left_link_1</child>
        <axis>
          <xyz>0 1 0</xyz>
          <limit>
            <effort>9.6</effort>
            <velocity>12.05</velocity>
            <lower>-1e+16</lower>
            <upper>1e+16</upper>
          </limit>
          <dynamics>
            <damping>0</damping>
            <friction>0</friction>
            <spring_reference>0</spring_reference>
            <spring_stiffness>0</spring_stiffness>
          </dynamics>
        </axis>
      </joint>
      <link name='wheel_left_link_1'>
        <pose relative_to='l4'>0 0 0 0 -0 0</pose>
        <inertial>
          <pose>0 0.026 -0 0 -0 0</pose>
          <mass>2.5</mass>
          <inertia>
            <ixx>0.025678</ixx>
            <ixy>0</ixy>
            <ixz>0</ixz>
            <iyy>0.046537</iyy>
            <iyz>0</iyz>
            <izz>0.025678</izz>
          </inertia>
        </inertial>
        <collision name='wheel_left_link_1_collision'>
          <pose>-0.00036 -0.215353 -0.099 0 -0 0</pose>
          <geometry>
            <mesh>
              <scale>0.001 0.001 0.001</scale>
              <uri>src/diablo_bot/description/meshes/wheel_right_link_1.stl</uri>
            </mesh>
          </geometry>
          <max_contacts>10</max_contacts>
          <surface>
            <contact>
              <ode/>
            </contact>
            <bounce/>
            <friction>
              <torsional>
                <ode/>
              </torsional>
              <ode/>
            </friction>
          </surface>
        </collision>
        <visual name='wheel_left_link_1_visual'>
          <pose>-0.00036 -0.215353 -0.099 0 -0 0</pose>
          <geometry>
            <mesh>
              <scale>0.001 0.001 0.001</scale>
              <uri>src/diablo_bot/description/meshes/wheel_right_link_1.stl</uri>
            </mesh>
          </geometry>
        </visual>
        <self_collide>0</self_collide>
        <enable_wind>0</enable_wind>
        <kinematic>0</kinematic>
      </link>
      <joint name='r1' type='revolute'>
        <pose relative_to='base_link'>0.00036 -0.053347 -0.121 0 -0 0</pose>
        <parent>base_link</parent>
        <child>motor_right_link_1</child>
        <axis>
          <xyz>0 -1 0</xyz>
          <limit>
            <effort>9.6</effort>
            <velocity>12.05</velocity>
            <lower>-1e+16</lower>
            <upper>1e+16</upper>
          </limit>
          <dynamics>
            <damping>0</damping>
            <friction>0</friction>
            <spring_reference>0</spring_reference>
            <spring_stiffness>0</spring_stiffness>
          </dynamics>
        </axis>
      </joint>
      <link name='motor_right_link_1'>
        <pose relative_to='r1'>0 0 0 0 -0 0</pose>
        <inertial>
          <pose>0.000158 -0.067982 -0.001799 0 -0 0</pose>
          <mass>4.65</mass>
          <inertia>
            <ixx>0.0300227</ixx>
            <ixy>4.25401e-05</ixy>
            <ixz>0.000229131</ixz>
            <iyy>0.0300775</iyy>
            <iyz>-0.000679053</iyz>
            <izz>0.0267843</izz>
          </inertia>
        </inertial>
        <collision name='motor_right_link_1_collision'>
          <pose>-0.00036 0.053347 -0.379 0 -0 0</pose>
          <geometry>
            <mesh>
              <scale>0.001 0.001 0.001</scale>
              <uri>src/diablo_bot/description/meshes/motor_right_link_1.stl</uri>
            </mesh>
          </geometry>
          <max_contacts>10</max_contacts>
          <surface>
            <contact>
              <ode/>
            </contact>
            <bounce/>
            <friction>
              <torsional>
                <ode/>
              </torsional>
              <ode/>
            </friction>
          </surface>
        </collision>
        <collision name='motor_right_link_1_fixed_joint_lump__leg_right_link_1_collision_1'>
          <pose>-0.00036 0.053347 -0.379 0 -0 0</pose>
          <geometry>
            <mesh>
              <scale>0.001 0.001 0.001</scale>
              <uri>src/diablo_bot/description/meshes/leg_right_link_1.stl</uri>
            </mesh>
          </geometry>
          <max_contacts>10</max_contacts>
          <surface>
            <contact>
              <ode/>
            </contact>
            <bounce/>
            <friction>
              <torsional>
                <ode/>
              </torsional>
              <ode/>
            </friction>
          </surface>
        </collision>
        <visual name='motor_right_link_1_visual'>
          <pose>-0.00036 0.053347 -0.379 0 -0 0</pose>
          <geometry>
            <mesh>
              <scale>0.001 0.001 0.001</scale>
              <uri>src/diablo_bot/description/meshes/motor_right_link_1.stl</uri>
            </mesh>
          </geometry>
        </visual>
        <visual name='motor_right_link_1_fixed_joint_lump__leg_right_link_1_visual_1'>
          <pose>-0.00036 0.053347 -0.379 0 -0 0</pose>
          <geometry>
            <mesh>
              <scale>0.001 0.001 0.001</scale>
              <uri>src/diablo_bot/description/meshes/leg_right_link_1.stl</uri>
            </mesh>
          </geometry>
        </visual>
        <self_collide>0</self_collide>
        <enable_wind>0</enable_wind>
        <kinematic>0</kinematic>
      </link>
      <joint name='r3' type='revolute'>
        <pose relative_to='motor_right_link_1'>0 -0.1341 -0.14 0 -0 0</pose>
        <parent>motor_right_link_1</parent>
        <child>leg2_right_link_1</child>
        <axis>
          <xyz>0 -1 0</xyz>
          <limit>
            <effort>9.6</effort>
            <velocity>12.05</velocity>
            <lower>-1e+16</lower>
            <upper>1e+16</upper>
          </limit>
          <dynamics>
            <damping>0</damping>
            <friction>0</friction>
            <spring_reference>0</spring_reference>
            <spring_stiffness>0</spring_stiffness>
          </dynamics>
        </axis>
      </joint>
      <link name='leg2_right_link_1'>
        <pose relative_to='r3'>0 0 0 0 -0 0</pose>
        <inertial>
          <pose>2e-06 -0.012347 -0.092364 0 -0 0</pose>
          <mass>0.05</mass>
          <inertia>
            <ixx>0.003787</ixx>
            <ixy>0</ixy>
            <ixz>0</ixz>
            <iyy>0.003963</iyy>
            <iyz>-5.8e-05</iyz>
            <izz>0.000327</izz>
          </inertia>
        </inertial>
        <collision name='leg2_right_link_1_collision'>
          <pose>-0.00036 0.187447 -0.239 0 -0 0</pose>
          <geometry>
            <mesh>
              <scale>0.001 0.001 0.001</scale>
              <uri>src/diablo_bot/description/meshes/leg2_right_link_1.stl</uri>
            </mesh>
          </geometry>
          <max_contacts>10</max_contacts>
          <surface>
            <contact>
              <ode/>
            </contact>
            <bounce/>
            <friction>
              <torsional>
                <ode/>
              </torsional>
              <ode/>
            </friction>
          </surface>
        </collision>
        <visual name='leg2_right_link_1_visual'>
          <pose>-0.00036 0.187447 -0.239 0 -0 0</pose>
          <geometry>
            <mesh>
              <scale>0.001 0.001 0.001</scale>
              <uri>src/diablo_bot/description/meshes/leg2_right_link_1.stl</uri>
            </mesh>
          </geometry>
        </visual>
        <self_collide>0</self_collide>
        <enable_wind>0</enable_wind>
        <kinematic>0</kinematic>
      </link>
      <joint name='r4' type='revolute'>
        <pose relative_to='leg2_right_link_1'>0 -0.0277 -0.14 0 -0 0</pose>
        <parent>leg2_right_link_1</parent>
        <child>wheel_right_link_1</child>
        <axis>
          <xyz>0 -1 0</xyz>
          <limit>
            <effort>9.6</effort>
            <velocity>12.05</velocity>
            <lower>-1e+16</lower>
            <upper>1e+16</upper>
          </limit>
          <dynamics>
            <damping>0</damping>
            <friction>0</friction>
            <spring_reference>0</spring_reference>
            <spring_stiffness>0</spring_stiffness>
          </dynamics>
        </axis>
      </joint>
      <link name='wheel_right_link_1'>
        <pose relative_to='r4'>0 0 0 0 -0 0</pose>
        <inertial>
          <pose>0 -0.026 -0 0 -0 0</pose>
          <mass>2.5</mass>
          <inertia>
            <ixx>0.025678</ixx>
            <ixy>0</ixy>
            <ixz>0</ixz>
            <iyy>0.046537</iyy>
            <iyz>0</iyz>
            <izz>0.025678</izz>
          </inertia>
        </inertial>
        <collision name='wheel_right_link_1_collision'>
          <pose>-0.00036 0.215147 -0.099 0 -0 0</pose>
          <geometry>
            <mesh>
              <scale>0.001 0.001 0.001</scale>
              <uri>src/diablo_bot/description/meshes/wheel_left_link_1.stl</uri>
            </mesh>
          </geometry>
          <max_contacts>10</max_contacts>
          <surface>
            <contact>
              <ode/>
            </contact>
            <bounce/>
            <friction>
              <torsional>
                <ode/>
              </torsional>
              <ode/>
            </friction>
          </surface>
        </collision>
        <visual name='wheel_right_link_1_visual'>
          <pose>-0.00036 0.215147 -0.099 0 -0 0</pose>
          <geometry>
            <mesh>
              <scale>0.001 0.001 0.001</scale>
              <uri>src/diablo_bot/description/meshes/wheel_left_link_1.stl</uri>
            </mesh>
          </geometry>
        </visual>
        <self_collide>0</self_collide>
        <enable_wind>0</enable_wind>
        <kinematic>0</kinematic>
      </link>
      <joint name='r_sho_pitch' type='revolute'>
        <pose relative_to='base_link'>-0.012051 -0.09965 0.26225 1.5708 -0 0</pose>
        <parent>base_link</parent>
        <child>r_sho_pitch_Link</child>
        <axis>
          <xyz>0 0 -1</xyz>
          <limit>
            <lower>-1.9635</lower>
            <upper>1.9635</upper>
            <effort>4.1</effort>
            <velocity>4.71</velocity>
          </limit>
          <dynamics>
            <spring_reference>0</spring_reference>
            <spring_stiffness>0</spring_stiffness>
          </dynamics>
        </axis>
      </joint>
      <link name='r_sho_pitch_Link'>
        <pose relative_to='r_sho_pitch'>0 0 0 0 -0 0</pose>
        <inertial>
          <pose>0.000541 -0 0.024565 0 -0 0</pose>
          <mass>0.0454925</mass>
          <inertia>
            <ixx>1.06543e-05</ixx>
            <ixy>3.1036e-20</ixy>
            <ixz>1.18102e-09</ixz>
            <iyy>1.2432e-05</iyy>
            <iyz>-3.20399e-20</iyz>
            <izz>7.52175e-06</izz>
          </inertia>
        </inertial>
        <collision name='r_sho_pitch_Link_collision'>
          <pose>0 0 0 0 -0 0</pose>
          <geometry>
            <mesh>
              <scale>1 1 1</scale>
              <uri>src/diablo_bot/description/meshes/r_sho_pitch_Link.STL</uri>
            </mesh>
          </geometry>
          <max_contacts>10</max_contacts>
          <surface>
            <contact>
              <ode/>
            </contact>
            <bounce/>
            <friction>
              <torsional>
                <ode/>
              </torsional>
              <ode/>
            </friction>
          </surface>
        </collision>
        <visual name='r_sho_pitch_Link_visual'>
          <pose>0 0 0 0 -0 0</pose>
          <geometry>
            <mesh>
              <scale>1 1 1</scale>
              <uri>src/diablo_bot/description/meshes/r_sho_pitch_Link.STL</uri>
            </mesh>
          </geometry>
        </visual>
        <self_collide>0</self_collide>
        <enable_wind>0</enable_wind>
        <kinematic>0</kinematic>
      </link>
      <joint name='r_sho_roll' type='revolute'>
        <pose relative_to='r_sho_pitch_Link'>0.0234 0 0.03735 3.14159 1.57079 3.14159</pose>
        <parent>r_sho_pitch_Link</parent>
        <child>r_sho_roll_Link</child>
        <axis>
          <xyz>0 0 -1</xyz>
          <limit>
            <lower>-1.6</lower>
            <upper>-0.9</upper>
            <effort>4.1</effort>
            <velocity>4.71</velocity>
          </limit>
          <dynamics>
            <spring_reference>0</spring_reference>
            <spring_stiffness>0</spring_stiffness>
          </dynamics>
        </axis>
      </joint>
      <link name='r_sho_roll_Link'>
        <pose relative_to='r_sho_roll'>0 0 0 0 -0 0</pose>
        <inertial>
          <pose>-0.114571 0.000361 -0.0234 0 -0 0</pose>
          <mass>0.0683067</mass>
          <inertia>
            <ixx>1.14189e-05</ixx>
            <ixy>-1.22523e-09</ixy>
            <ixz>7.03693e-13</ixz>
            <iyy>2.35951e-05</iyy>
            <iyz>1.5685e-13</iyz>
            <izz>2.34186e-05</izz>
          </inertia>
        </inertial>
        <collision name='r_sho_roll_Link_collision'>
          <pose>0 0 0 0 -0 0</pose>
          <geometry>
            <mesh>
              <scale>1 1 1</scale>
              <uri>src/diablo_bot/description/meshes/r_sho_roll_Link.STL</uri>
            </mesh>
          </geometry>
          <max_contacts>10</max_contacts>
          <surface>
            <contact>
              <ode/>
            </contact>
            <bounce/>
            <friction>
              <torsional>
                <ode/>
              </torsional>
              <ode/>
            </friction>
          </surface>
        </collision>
        <visual name='r_sho_roll_Link_visual'>
          <pose>0 0 0 0 -0 0</pose>
          <geometry>
            <mesh>
              <scale>1 1 1</scale>
              <uri>src/diablo_bot/description/meshes/r_sho_roll_Link.STL</uri>
            </mesh>
          </geometry>
        </visual>
        <self_collide>0</self_collide>
        <enable_wind>0</enable_wind>
        <kinematic>0</kinematic>
      </link>
      <joint name='r_el' type='revolute'>
        <pose relative_to='r_sho_roll_Link'>-0.14975 0.0234 -0.0234 -1.5708 0 0</pose>
        <parent>r_sho_roll_Link</parent>
        <child>r_el_Link</child>
        <axis>
          <xyz>0 0 -1</xyz>
          <limit>
            <lower>-1.57</lower>
            <upper>0</upper>
            <effort>4.1</effort>
            <velocity>4.71</velocity>
          </limit>
          <dynamics>
            <spring_reference>0</spring_reference>
            <spring_stiffness>0</spring_stiffness>
          </dynamics>
        </axis>
      </joint>
      <link name='r_el_Link'>
        <pose relative_to='r_el'>0 0 0 0 -0 0</pose>
        <inertial>
          <pose>-0.068098 0.001511 -0.026841 0 -0 0</pose>
          <mass>0.305317</mass>
          <inertia>
            <ixx>0.0975727</ixx>
            <ixy>-4.21458e-05</ixy>
            <ixz>0.000414753</ixz>
            <iyy>1.0178</iyy>
            <iyz>0.00159474</iyz>
            <izz>0.931969</izz>
          </inertia>
        </inertial>
        <collision name='r_el_Link_collision'>
          <pose>0 0 0 0 -0 0</pose>
          <geometry>
            <mesh>
              <scale>1 1 1</scale>
              <uri>src/diablo_bot/description/meshes/r_el_Link.STL</uri>
            </mesh>
          </geometry>
          <max_contacts>10</max_contacts>
          <surface>
            <contact>
              <ode/>
            </contact>
            <bounce/>
            <friction>
              <torsional>
                <ode/>
              </torsional>
              <ode/>
            </friction>
          </surface>
        </collision>
        <collision name='r_el_Link_fixed_joint_lump__r_wrist_Link_collision_1'>
          <pose>-0.091 -0.000113 -0.023557 1.5708 0 -1.5708</pose>
          <geometry>
            <mesh>
              <scale>1 1 1</scale>
              <uri>src/diablo_bot/description/meshes/r_wrist_Link.STL</uri>
            </mesh>
          </geometry>
          <max_contacts>10</max_contacts>
          <surface>
            <contact>
              <ode/>
            </contact>
            <bounce/>
            <friction>
              <torsional>
                <ode/>
              </torsional>
              <ode/>
            </friction>
          </surface>
        </collision>
        <collision name='r_el_Link_fixed_joint_lump__r_index_base_Link_collision_2'>
          <pose>-0.18594 0.014369 -0.008534 -3.14159 -0 3.14159</pose>
          <geometry>
            <mesh>
              <scale>1 1 1</scale>
              <uri>src/diablo_bot/description/meshes/r_index_base_Link.STL</uri>
            </mesh>
          </geometry>
          <max_contacts>10</max_contacts>
          <surface>
            <contact>
              <ode/>
            </contact>
            <bounce/>
            <friction>
              <torsional>
                <ode/>
              </torsional>
              <ode/>
            </friction>
          </surface>
        </collision>
        <collision name='r_el_Link_fixed_joint_lump__r_index_middle_Link_collision_3'>
          <pose>-0.200475 0.021152 -0.007769 -3.14159 -0 3.14159</pose>
          <geometry>
            <mesh>
              <scale>1 1 1</scale>
              <uri>src/diablo_bot/description/meshes/r_index_middle_Link.STL</uri>
            </mesh>
          </geometry>
          <max_contacts>10</max_contacts>
          <surface>
            <contact>
              <ode/>
            </contact>
            <bounce/>
            <friction>
              <torsional>
                <ode/>
              </torsional>
              <ode/>
            </friction>
          </surface>
        </collision>
        <collision name='r_el_Link_fixed_joint_lump__r_index_tip_Link_collision_4'>
          <pose>-0.215391 0.026552 -0.005682 -3.14159 -0 3.14159</pose>
          <geometry>
            <mesh>
              <scale>1 1 1</scale>
              <uri>src/diablo_bot/description/meshes/r_index_tip_Link.STL</uri>
            </mesh>
          </geometry>
          <max_contacts>10</max_contacts>
          <surface>
            <contact>
              <ode/>
            </contact>
            <bounce/>
            <friction>
              <torsional>
                <ode/>
              </torsional>
              <ode/>
            </friction>
          </surface>
        </collision>
        <collision name='r_el_Link_fixed_joint_lump__r_mid_base_Link_collision_5'>
          <pose>-0.184747 0.013642 -0.048987 -3.14159 -0 3.14159</pose>
          <geometry>
            <mesh>
              <scale>1 1 1</scale>
              <uri>src/diablo_bot/description/meshes/r_mid_base_Link.STL</uri>
            </mesh>
          </geometry>
          <max_contacts>10</max_contacts>
          <surface>
            <contact>
              <ode/>
            </contact>
            <bounce/>
            <friction>
              <torsional>
                <ode/>
              </torsional>
              <ode/>
            </friction>
          </surface>
        </collision>
        <collision name='r_el_Link_fixed_joint_lump__r_mid_middle_Link_collision_6'>
          <pose>-0.198972 0.020236 -0.052455 -3.14159 -0 3.14159</pose>
          <geometry>
            <mesh>
              <scale>1 1 1</scale>
              <uri>src/diablo_bot/description/meshes/r_mid_middle_Link.STL</uri>
            </mesh>
          </geometry>
          <max_contacts>10</max_contacts>
          <surface>
            <contact>
              <ode/>
            </contact>
            <bounce/>
            <friction>
              <torsional>
                <ode/>
              </torsional>
              <ode/>
            </friction>
          </surface>
        </collision>
        <collision name='r_el_Link_fixed_joint_lump__r_mid_tip_Link_collision_7'>
          <pose>-0.213888 0.025636 -0.054543 -3.14159 -0 3.14159</pose>
          <geometry>
            <mesh>
              <scale>1 1 1</scale>
              <uri>src/diablo_bot/description/meshes/r_mid_tip_Link.STL</uri>
            </mesh>
          </geometry>
          <max_contacts>10</max_contacts>
          <surface>
            <contact>
              <ode/>
            </contact>
            <bounce/>
            <friction>
              <torsional>
                <ode/>
              </torsional>
              <ode/>
            </friction>
          </surface>
        </collision>
        <collision name='r_el_Link_fixed_joint_lump__r_thumb_base_Link_collision_8'>
          <pose>-0.169953 -0.026986 -0.028807 -3.14159 -0 3.14159</pose>
          <geometry>
            <mesh>
              <scale>1 1 1</scale>
              <uri>src/diablo_bot/description/meshes/r_thumb_base_Link.STL</uri>
            </mesh>
          </geometry>
          <max_contacts>10</max_contacts>
          <surface>
            <contact>
              <ode/>
            </contact>
            <bounce/>
            <friction>
              <torsional>
                <ode/>
              </torsional>
              <ode/>
            </friction>
          </surface>
        </collision>
        <collision name='r_el_Link_fixed_joint_lump__r_thumb_middle_Link_collision_9'>
          <pose>-0.175425 -0.042021 -0.030171 -3.14159 -0 3.14159</pose>
          <geometry>
            <mesh>
              <scale>1 1 1</scale>
              <uri>src/diablo_bot/description/meshes/r_thumb_middle_Link.STL</uri>
            </mesh>
          </geometry>
          <max_contacts>10</max_contacts>
          <surface>
            <contact>
              <ode/>
            </contact>
            <bounce/>
            <friction>
              <torsional>
                <ode/>
              </torsional>
              <ode/>
            </friction>
          </surface>
        </collision>
        <collision name='r_el_Link_fixed_joint_lump__r_thumb_tip_Link_collision_10'>
          <pose>-0.182187 -0.056522 -0.030171 -3.14159 -0 3.14159</pose>
          <geometry>
            <mesh>
              <scale>1 1 1</scale>
              <uri>src/diablo_bot/description/meshes/r_thumb_tip_Link.STL</uri>
            </mesh>
          </geometry>
          <max_contacts>10</max_contacts>
          <surface>
            <contact>
              <ode/>
            </contact>
            <bounce/>
            <friction>
              <torsional>
                <ode/>
              </torsional>
              <ode/>
            </friction>
          </surface>
        </collision>
        <visual name='r_el_Link_visual'>
          <pose>0 0 0 0 -0 0</pose>
          <geometry>
            <mesh>
              <scale>1 1 1</scale>
              <uri>src/diablo_bot/description/meshes/r_el_Link.STL</uri>
            </mesh>
          </geometry>
        </visual>
        <visual name='r_el_Link_fixed_joint_lump__r_wrist_Link_visual_1'>
          <pose>-0.091 -0.000113 -0.023557 1.5708 0 -1.5708</pose>
          <geometry>
            <mesh>
              <scale>1 1 1</scale>
              <uri>src/diablo_bot/description/meshes/r_wrist_Link.STL</uri>
            </mesh>
          </geometry>
        </visual>
        <visual name='r_el_Link_fixed_joint_lump__r_index_base_Link_visual_2'>
          <pose>-0.18594 0.014369 -0.008534 -3.14159 -0 3.14159</pose>
          <geometry>
            <mesh>
              <scale>1 1 1</scale>
              <uri>src/diablo_bot/description/meshes/r_index_base_Link.STL</uri>
            </mesh>
          </geometry>
        </visual>
        <visual name='r_el_Link_fixed_joint_lump__r_index_middle_Link_visual_3'>
          <pose>-0.200475 0.021152 -0.007769 -3.14159 -0 3.14159</pose>
          <geometry>
            <mesh>
              <scale>1 1 1</scale>
              <uri>src/diablo_bot/description/meshes/r_index_middle_Link.STL</uri>
            </mesh>
          </geometry>
        </visual>
        <visual name='r_el_Link_fixed_joint_lump__r_index_tip_Link_visual_4'>
          <pose>-0.215391 0.026552 -0.005682 -3.14159 -0 3.14159</pose>
          <geometry>
            <mesh>
              <scale>1 1 1</scale>
              <uri>src/diablo_bot/description/meshes/r_index_tip_Link.STL</uri>
            </mesh>
          </geometry>
        </visual>
        <visual name='r_el_Link_fixed_joint_lump__r_mid_base_Link_visual_5'>
          <pose>-0.184747 0.013642 -0.048987 -3.14159 -0 3.14159</pose>
          <geometry>
            <mesh>
              <scale>1 1 1</scale>
              <uri>src/diablo_bot/description/meshes/r_mid_base_Link.STL</uri>
            </mesh>
          </geometry>
        </visual>
        <visual name='r_el_Link_fixed_joint_lump__r_mid_middle_Link_visual_6'>
          <pose>-0.198972 0.020236 -0.052455 -3.14159 -0 3.14159</pose>
          <geometry>
            <mesh>
              <scale>1 1 1</scale>
              <uri>src/diablo_bot/description/meshes/r_mid_middle_Link.STL</uri>
            </mesh>
          </geometry>
        </visual>
        <visual name='r_el_Link_fixed_joint_lump__r_mid_tip_Link_visual_7'>
          <pose>-0.213888 0.025636 -0.054543 -3.14159 -0 3.14159</pose>
          <geometry>
            <mesh>
              <scale>1 1 1</scale>
              <uri>src/diablo_bot/description/meshes/r_mid_tip_Link.STL</uri>
            </mesh>
          </geometry>
        </visual>
        <visual name='r_el_Link_fixed_joint_lump__r_thumb_base_Link_visual_8'>
          <pose>-0.169953 -0.026986 -0.028807 -3.14159 -0 3.14159</pose>
          <geometry>
            <mesh>
              <scale>1 1 1</scale>
              <uri>src/diablo_bot/description/meshes/r_thumb_base_Link.STL</uri>
            </mesh>
          </geometry>
        </visual>
        <visual name='r_el_Link_fixed_joint_lump__r_thumb_middle_Link_visual_9'>
          <pose>-0.175425 -0.042021 -0.030171 -3.14159 -0 3.14159</pose>
          <geometry>
            <mesh>
              <scale>1 1 1</scale>
              <uri>src/diablo_bot/description/meshes/r_thumb_middle_Link.STL</uri>
            </mesh>
          </geometry>
        </visual>
        <visual name='r_el_Link_fixed_joint_lump__r_thumb_tip_Link_visual_10'>
          <pose>-0.182187 -0.056522 -0.030171 -3.14159 -0 3.14159</pose>
          <geometry>
            <mesh>
              <scale>1 1 1</scale>
              <uri>src/diablo_bot/description/meshes/r_thumb_tip_Link.STL</uri>
            </mesh>
          </geometry>
        </visual>
        <self_collide>0</self_collide>
        <enable_wind>0</enable_wind>
        <kinematic>0</kinematic>
      </link>
      <static>0</static>
      <plugin name='diff_drive' filename='libgazebo_ros_diff_drive.so'>
        <left_joint>l4</left_joint>
        <right_joint>r4</right_joint>
        <wheel_separation>0.5</wheel_separation>
        <wheel_diameter>0.1</wheel_diameter>
        <max_wheel_torque>200</max_wheel_torque>
        <max_wheel_acceleration>10.0</max_wheel_acceleration>
        <odometry_frame>odom</odometry_frame>
        <robot_base_frame>base_link</robot_base_frame>
        <publish_odom>1</publish_odom>
        <publish_odom_tf>1</publish_odom_tf>
        <publish_wheel_tf>1</publish_wheel_tf>
      </plugin>
      <pose>0 0 0 0 -0 0</pose>
    </model>
    <state world_name='default'>
      <sim_time>174 880000000</sim_time>
      <real_time>181 599426732</real_time>
      <wall_time>1733203934 889527387</wall_time>
      <iterations>174880</iterations>
      <model name='ground_plane'>
        <pose>0 0 0 0 -0 0</pose>
        <scale>1 1 1</scale>
        <link name='link'>
          <pose>0 0 0 0 -0 0</pose>
          <velocity>0 0 0 0 -0 0</velocity>
          <acceleration>0 0 0 0 -0 0</acceleration>
          <wrench>0 0 0 0 -0 0</wrench>
        </link>
      </model>
      <model name='my_bot'>
        <pose>-1.82937 -4.7015 0.239584 1e-05 7.6e-05 -0.481658</pose>
        <scale>1 1 1</scale>
        <link name='base_link'>
          <pose>-1.82937 -4.7015 0.239584 1e-05 7.6e-05 -0.481658</pose>
          <velocity>0.002945 -0.000915 -0.008466 0.001883 0.01407 0.002081</velocity>
          <acceleration>0.036712 0.344579 -7.09144 0.352273 -1.49376 2.1022</acceleration>
          <wrench>0.31617 2.96759 -61.073 0 -0 0</wrench>
        </link>
        <link name='l_el_Link'>
          <pose>-1.76075 -4.54418 0.354168 -0.441158 1.49044 0.646729</pose>
          <velocity>0.006382 0.011702 -0.000759 0.135889 0.041394 0.006859</velocity>
          <acceleration>0.759989 -0.318399 -5.97877 0.009047 0.03962 -0.162409</acceleration>
          <wrench>0.232038 -0.097213 -1.82542 0 -0 0</wrench>
        </link>
        <link name='l_sho_pitch_Link'>
          <pose>-1.79387 -4.60762 0.501829 1.57083 -0.000173 2.65994</pose>
          <velocity>0.006133 -0.001271 -0.007193 0.035934 0.05878 0.006115</velocity>
          <acceleration>0.603391 2.26002 -6.9316 -0.463217 0.268708 -1.49792</acceleration>
          <wrench>0.02745 0.102814 -0.315336 0 -0 0</wrench>
        </link>
        <link name='l_sho_roll_Link'>
          <pose>-1.75583 -4.58535 0.50182 1.56749 -1.49812 -2.04913</pose>
          <velocity>0.003308 -0.002725 -0.00466 0.101193 -0.023382 -0.000112</velocity>
          <acceleration>0.625883 0.296305 -5.8041 -2.51621 1.2664 -2.29665</acceleration>
          <wrench>0.042752 0.02024 -0.396459 0 -0 0</wrench>
        </link>
        <link name='leg2_left_link_1'>
          <pose>-1.81414 -4.49772 0.232595 1.1e-05 -0.113105 -0.481654</pose>
          <velocity>0.001443 0.00064 -0.011152 -0.003987 0.00081 0.003839</velocity>
          <acceleration>3.48415 0.010495 -16.3646 0.4025 1.12484 -1.33995</acceleration>
          <wrench>0.174207 0.000525 -0.818229 0 -0 0</wrench>
        </link>
        <link name='leg2_right_link_1'>
          <pose>-1.83308 -4.91107 0.222837 1.5e-05 -0.392566 -0.481677</pose>
          <velocity>-0.004092 0.003808 0.00575 -0.020546 -0.012791 0.019562</velocity>
          <acceleration>-4.31515 4.4601 12.5693 -0.314372 -1.08783 1.93423</acceleration>
          <wrench>-0.215757 0.223005 0.628465 0 -0 0</wrench>
        </link>
        <link name='motor_left_link_1'>
          <pose>-1.80425 -4.6542 0.118585 3.14158 0.619252 2.65993</pose>
          <velocity>0.001157 -0.000637 -0.008742 -0.006469 -0.001846 0.001978</velocity>
          <acceleration>-0.208956 0.197202 -8.033 -1.56733 1.21457 2.5526</acceleration>
          <wrench>-0.971644 0.91699 -37.3534 0 -0 0</wrench>
        </link>
        <link name='motor_right_link_1'>
          <pose>-1.85377 -4.74894 0.118584 3.14158 -0.730812 2.65994</pose>
          <velocity>0.001363 -0.000745 -0.008126 -0.042631 -0.06874 0.002307</velocity>
          <acceleration>0.068721 0.050338 -6.07434 2.38297 0.977344 -3.09529</acceleration>
          <wrench>0.319554 0.234074 -28.2457 0 -0 0</wrench>
        </link>
        <link name='r_el_Link'>
          <pose>-1.9205 -4.84804 0.35437 -1.16496 -1.37066 2.2618</pose>
          <velocity>-0.024493 -0.00377 -0.000994 -0.114162 -0.016801 0.01591</velocity>
          <acceleration>0.426504 0.763763 -5.93408 -0.11569 0.195061 0.953499</acceleration>
          <wrench>0.130219 0.23319 -1.81177 0 -0 0</wrench>
        </link>
        <link name='r_sho_pitch_Link'>
          <pose>-1.8862 -4.78424 0.501827 1.57072 0.005662 -0.481655</pose>
          <velocity>0.006654 -0.001503 -0.0068 0.097163 0.169034 0.002366</velocity>
          <acceleration>1.12296 1.96301 -6.3788 2.34083 -0.376144 1.73969</acceleration>
          <wrench>0.051086 0.089302 -0.290188 0 -0 0</wrench>
        </link>
        <link name='r_sho_roll_Link'>
          <pose>-1.88276 -4.82819 0.501687 1.64395 -1.492 1.01621</pose>
          <velocity>0.00734 -0.000633 -0.010148 -0.020547 0.214499 -0.002972</velocity>
          <acceleration>0.605328 1.09259 -6.19817 2.26561 -0.509369 0.823031</acceleration>
          <wrench>0.041348 0.074631 -0.423377 0 -0 0</wrench>
        </link>
        <link name='wheel_left_link_1'>
          <pose>-1.78731 -4.48049 0.093489 2.3e-05 -1.19058 -0.481675</pose>
          <velocity>0.001145 1.7e-05 -0.010884 -0.003233 0.000415 0.002658</velocity>
          <acceleration>2.22701 -0.128555 -14.3 -2.29091 0.591106 1.4501</acceleration>
          <wrench>5.56752 -0.321387 -35.7501 0 -0 0</wrench>
        </link>
        <link name='wheel_right_link_1'>
          <pose>-1.79844 -4.96043 0.093485 7e-06 -0.541574 -0.481671</pose>
          <velocity>-0.001834 0.00203 0.005649 -0.019574 -0.014746 0.019192</velocity>
          <acceleration>-2.21132 3.43232 11.8136 2.14526 -0.298545 -0.712484</acceleration>
          <wrench>-5.5283 8.58079 29.534 0 -0 0</wrench>
        </link>
      </model>
      <light name='sun'>
        <pose>0 0 10 0 -0 0</pose>
      </light>
    </state>
    <gui fullscreen='0'>
      <camera name='user_camera'>
        <pose>2.42361 -7.65065 1.81433 0 0.275643 2.35619</pose>
        <view_controller>orbit</view_controller>
        <projection_type>perspective</projection_type>
      </camera>
    </gui>
  </world>
</sdf>
